// theirs
const fetch = require('node-fetch')
const debug = require('debug')('now:sh:get-user')

// ours
const error = require('../../../util/output/error')

const getUser = async ({ apiUrl, token }) => {
  debug('start')
  const url = apiUrl + '/www/user'
  const headers = {
    Authorization: `Bearer ${token}`
  }

  debug('GET /www/user')

  let res
  try {
    res = await fetch(url, { headers })
  } catch (err) {
    debug(`error fetching /www/user: $O`, err.stack)
    throw new Error(
      error(
        `An unexpected error occurred while trying to fetch your personal details: ${err.message}`
      )
    )
  }

  debug('parsing response from GET /www/user')

  let body
  try {
    body = await res.json()
  } catch (err) {
    debug(
      `error parsing the response from /www/user as JSON â€“ got %O`,
      err.stack
    )
    throw new Error(
      error(
        `An unexpected error occurred while trying to fetch your personal details: ${err.message}`
      )
    )
  }

  const { user } = body

  // this is pretty much useless
  delete user.billingChecked

  return user
}

module.exports = getUser
